Workbook

Sheet General
A2: GUI section | B2: Function description | C2: Button type | D2: Type | E2: EPICS Variable (PVs) | F2: PLC Variable
A3: Motion control - manual - motors | B3: Home Reverse | C3: Action | D3: Action | E3: mc:m:motor:XXX:Home:reverse_W
B4: Home Forward | C4: Action | D4: Action | E4: mc:m:motor:XXX:Home:forward_W
B5: Reverse per step | C5: Action | D5: Action | E5: mc:m:motor:XXX:Reverse:perStep_W
B6: Forward per step | C6: Action | D6: Action | E6: mc:m:motor:XXX:Forward:perStep_W
B7: Reverse in position | C7: LED | D7: Read | E7: mc:m:motor:XXX:Reverse:inPosition_R
B8: Forward in position | C8: LED | D8: Read | E8: mc:m:motor:XXX:Forward:inPosition_R
B9: Motor position (in step) | C9: Text Update | D9: Read | E9: mc:m:motor:XXX:ActPosition_R
B10: Motor stop | C10: Action | D10: Action | E10: mc:m:motor:XXX:stop_W
B11: Maximum settable speed | C11: Spinner | D11: Action | E11: mc:m:motor:XXX:MaxSpeed_W
B12: Initial speed before acceleration | C12: Spinner | D12: Action | E12: mc:m:motor:XXX:initialAcc_W
B13: Setting speed | C13: Spinner | D13: Action | E13: mc:m:motor:XXX:speed_W
B14: Revolutions per second | C14: Text Update | D14: Read | E14: mc:m:motor:XXX:speed_R
B15: Reset errors | C15: Action | D15: Action | E15: mc:m:motor:XXX:quitError_W
B16: Motor status | C16: Byte Monitor | D16: Read
A17: Motion control - manual - solenoids | B17: Lock 1 extract | C17: Action | D17: Action | E17: mc:m:solenoid:lock:1:extract_W
B18: Lock 1 insert | C18: Action | D18: Action | E18: mc:m:solenoid:lock:1:insert_W
B19: Lock 2 extract | C19: Action | D19: Action | E19: mc:m:solenoid:lock:2:extract_W
B20: Lock 2 insert | C20: Action | D20: Action | E20: mc:m:solenoid:lock:2:insert_W
B21: Lock 1 extracted | C21: LED | D21: Read | E21: mc:m:solenoid:lock:1:extract_R
B22: Lock 1 inserted | C22: LED | D22: Read | E22: mc:m:solenoid:lock:1:insert_R
B23: Lock 2 extracted | C23: LED | D23: Read | E23: mc:m:solenoid:lock:2:extract_R
B24: Lock 2 inserted | C24: LED | D24: Read | E24: mc:m:solenoid:lock:2:insert_R
A25: Motion control - manual - monitoring | B25: Motors box temperature | C25: Text Update | D25: Read | F25: Read from thermometer
A26: Motion control - automatic - main control | B26: Home | C26: Boolean Button | D26: Action | E26: mc:a:maincontrol:home_W
B27: Charge phase | C27: Boolean Button | D27: Action | E27: mc:a:maincontrol:charge_W
B28: Irradiation phase | C28: Boolean Button | D28: Action | E28: mc:a:maincontrol:irradiationphase_W
B29: Couple | C29: Boolean Button | D29: Action | E29: mc:a:maincontrol:coupled_W
B30: MPS request - irradiation | C30: Boolean Button | D30: Action | E30: mc:a:maincontrol:MPS:ReqIrradiation_W
B31: Collimator extract | C31: Boolean Button | D31: Action | E31: mc:a:maincontrol:collimator:extract_W
B32: Irradiation start | C32: Boolean Button | D32: Action | E32: mc:a:maincontrol:Irradiation:start_W
B33: Irradiation over | C33: Boolean Button | D33: Action | E33: mc:a:maincontrol:Irradiation:Over_W
B34: Tablet 1 irradiation | C34: LED | D34: Read | E34: mc:a:maincontrol:Tablet:Irradiation:1_R
B35: Tablet 2 irradiation | C35: LED | D35: Read | E35: mc:a:maincontrol:Tablet:Irradiation:2_R
B36: Tablet 3 irradiation | C36: LED | D36: Read | E36: mc:a:maincontrol:Tablet:Irradiation:3_R
B37: Tablet irradiation finish | C37: Boolean Button | D37: Action
B38: MPS request - decouple | C38: Boolean Button | D38: Action | E38: mc:a:maincontrol:MPS:ReqDecouple_W
B39: Decoupled | C39: LED | D39: Read | E39: mc:a:maincontrol:Decoupled_R
B40: Measurement start | C40: Boolean Button | D40: Action | E40: mc:a:maincontrol:Measurement:start_W
B41: Measurement over | C41: Boolean Button | D41: Action | E41: mc:a:maincontrol:Measurement:over_W
...

Sheet General_Update
A1: GUI section | C1: Function description | D1: Button type | E1: Type | F1: EPICS Variable (PVs) | G1: PLC Variable | H1: Modbus addresses
A2: MotionControl-automatic-stepSet | C2: M1 moving step | D2: Spinner | E2: Action | F2: mc:a:stepSetting:motor:1:movingStep_R | H2: 500
C3: M1 correction step | D3: Spinner | E3: Action | F3: mc:a:stepSetting:motor:1:CorrectionStep_W | H3: 502
C4: M3 moving step | D4: Spinner | E4: Action | F4: mc:a:stepSetting:motor:3:movingStep_R | H4: 504
C5: M3 correction step | D5: Spinner | E5: Action | F5: mc:a:stepSetting:motor:3:CorrectionStep_W | H5: 506
C6: M4 Moving Step | D6: Spinner | E6: Action | F6: mc:a:stepSetting:motor:4:movingStep_R | L6: =34/143*100 -> 23.776224
C7: M4 Offset Step | D7: Spinner | E7: Action | F7: mc:a:stepSetting:motor:4:OffsetStep_W
C8: M5 charging step 1 | D8: Spinner | E8: Action | F8: mc:a:stepSetting:motor:5:chargingStep:1_W | H8: 508
C9: M5 charging step 2 | D9: Spinner | E9: Action | F9: mc:a:stepSetting:motor:5:chargingStep:2_W | H9: 510
C10: M5 charging step 3 | D10: Spinner | E10: Action | F10: mc:a:stepSetting:motor:5:chargingStep:3_W | H10: 512
C11: M5 irradiation step 1 | D11: Spinner | E11: Action | F11: mc:a:stepSetting:motor:5:IrradiationStep:1_W | H11: 514
C12: M5 irradiation step 2 | D12: Spinner | E12: Action | F12: mc:a:stepSetting:motor:5:IrradiationStep:2_W | H12: 516
C13: M5 irradiation step 3 | D13: Spinner | E13: Action | F13: mc:a:stepSetting:motor:5:IrradiationStep:3_W | H13: 518
C14: M5 discharging step 1 | D14: Spinner | E14: Action | F14: mc:a:stepSetting:motor:5:DischargingStep:1_W | H14: 520
C15: M5 discharging step 2 | D15: Spinner | E15: Action | F15: mc:a:stepSetting:motor:5:DischargingStep:2_W | H15: 522
C16: M5 discharging step 3 | D16: Spinner | E16: Action | F16: mc:a:stepSetting:motor:5:DischargingStep:3_W | H16: 524
C17: Motor power state | D17: LED | E17: Read | F17: mc:a:stepSetting:Motor:xxx:power:state_R | H17: 550
C18: Motor in movement | D18: LED | E18: Read | F18: mc:a:stepSetting:Motor:xxx:movement_R
C19: Motor in position | D19: LED | E19: Read | F19: mc:a:stepSetting:Motor:xxx:inPosition_R
C20: Motor Coupled | D20: LED | E20: Read | H20: 552
C21: Motor home state | D21: LED | E21: Read | F21: mc:a:stepSetting:Motor:xxx:home:state_R | H21: 554
C22: Motor power state | D22: LED | E22: Read | F22: mc:a:stepSetting:Motor:xxx:power:state_R | H22: 570
C23: Motor in movement | D23: LED | E23: Read | F23: mc:a:stepSetting:Motor:xxx:movement_R
C24: Motor in position | D24: LED | E24: Read | F24: mc:a:stepSetting:Motor:xxx:inPosition_R
C25: Motor home state | D25: LED | E25: Read | F25: mc:a:stepSetting:Motor:xxx:home:state_R | H25: 572
C26: Motor power state | D26: LED | E26: Read | F26: mc:a:stepSetting:Motor:xxx:power:state_R | H26: 580
C27: Motor in movement | D27: LED | E27: Read | F27: mc:a:stepSetting:Motor:xxx:movement_R
C28: Motor in position | D28: LED | E28: Read | F28: mc:a:stepSetting:Motor:xxx:inPosition_R
C29: Motor home state | D29: LED | E29: Read | F29: mc:a:stepSetting:Motor:xxx:home:state_R | H29: 582
C30: Motor Coupled | D30: LED | E30: Read | H30: 584
C31: Motor power state | D31: LED | E31: Read | F31: mc:a:stepSetting:Motor:xxx:power:state_R | H31: 590
C32: Motor in movement | D32: LED | E32: Read | F32: mc:a:stepSetting:Motor:xxx:movement_R
C33: Motor in position | D33: LED | E33: Read | F33: mc:a:stepSetting:Motor:xxx:inPosition_R
C34: Motor home state | D34: LED | E34: Read | F34: mc:a:stepSetting:Motor:xxx:home:state_R | H34: 592
C35: Motor power state | D35: LED | E35: Read | F35: mc:a:stepSetting:Motor:xxx:power:state_R | H35: 600
C36: Motor in movement | D36: LED | E36: Read | F36: mc:a:stepSetting:Motor:xxx:movement_R
C37: Motor in position | D37: LED | E37: Read | F37: mc:a:stepSetting:Motor:xxx:inPosition_R
C38: Motor home state | D38: LED | E38: Read | F38: mc:a:stepSetting:Motor:xxx:home:state_R | H38: 602
C39: Motor power state | D39: LED | E39: Read | F39: mc:a:stepSetting:Motor:xxx:power:state_R | H39: 610
C40: Motor in movement | D40: LED | E40: Read | F40: mc:a:stepSetting:Motor:xxx:movement_R
...

Sheet Motion control-manual - motor X
A3: GUI section | B3: Motor | C3: Function description | D3: Button type | E3: Type | F3: EPICS Variable (PVs) | G3: PLC Variable | H3: Modbus Addresses | I3: plc port name | M3: Function description | N3: Button type | O3: Type | P3: EPICS Variable (PVs) | Q3: PLC Variable | R3: Modbus Addresses | S3: plc port name | V3: Function description | W3: Button type | X3: Type | Y3: EPICS Variable (PVs) | Z3: PLC Variable | AA3: Modbus Addresses | AB3: plc port name
A4: Motion control - manual - motors | B4: Motor 1 | C4: Power On | D4: Action | E4: Action | F4: mc:m:motor:XXX:powerOn_W | H4: 10 | I4: MC_M_M_W | L4: Motor 1 | M4: Power On | N4: Action | O4: Action | P4: mc:m:motor:XXX:powerOn_W | R4: 10 | S4: MC_M_M_W | U4: Motor 1 | V4: Motor position | W4: Text entry | X4: Read | Y4: mc:m:motor:XXX:ActPosition_R | Z4: _LMCAxis_M1.ActPos | AA4: 200 | AB4: MC_M_M_R
C5: Power Off | D5: Action | E5: Action | F5: mc:m:motor:XXX:powerOff_W | H5: 12 | I5: MC_M_M_W | M5: Power Off | N5: Action | O5: Action | P5: mc:m:motor:XXX:powerOff_W | R5: 12 | S5: MC_M_M_W | V5: Error | W5: LED | X5: Read | Y5: mc:m:motor:XXX:Error_R | AA5: 202 | AB5: MC_M_M_R
C6: Setting speed | D6: Spinner | E6: Action | F6: mc:m:motor:XXX:speed_W | H6: 14 | I6: MC_M_M_W | M6: Setting speed | N6: Spinner | O6: Action | P6: mc:m:motor:XXX:speed_W | R6: 14 | S6: MC_M_M_W | V6: Forward in position | W6: LED | X6: Read | Y6: mc:m:motor:XXX:Forward:inPosition_R | AA6: 204 | AB6: MC_M_M_R
C7: Start Movement | D7: Action | E7: Action | F7: mc:m:motor:XXX:start_W | H7: 16 | I7: MC_M_M_W | M7: Start Movement | N7: Action | O7: Action | P7: mc:m:motor:XXX:start_W | R7: 16 | S7: MC_M_M_W | V7: Reverse in position | W7: LED | X7: Read | Y7: mc:m:motor:XXX:Reverse:inPosition_R | AA7: 206 | AB7: MC_M_M_R
C8: Motor stop | D8: Action | E8: Action | F8: mc:m:motor:XXX:stop_W | H8: 18 | I8: MC_M_M_W | M8: Motor stop | N8: Action | O8: Action | P8: mc:m:motor:XXX:stop_W | R8: 18 | S8: MC_M_M_W | V8: Maximum settable speed | W8: Text Update | X8: Read | Y8: mc:m:motor:XXX:MaxSpeed_R | AA8: 208 | AB8: MC_M_M_R
C9: Direction | D9: Boolean | E9: Action | F9: mc:m:motor:XXX:direction_W | H9: 20 | I9: MC_M_M_W | M9: Direction | N9: Boolean | O9: Action | P9: mc:m:motor:XXX:direction_W | R9: 20 | S9: MC_M_M_W | V9: Minimum settable speed | W9: Text Update | X9: Read | Y9: mc:m:motor:XXX:MinSpeed_R | AA9: 210 | AB9: MC_M_M_R
C10: Reset errors | D10: Action | E10: Action | F10: mc:m:motor:XXX:quitError_W | H10: 22 | I10: MC_M_M_W | M10: Reset errors | N10: Action | O10: Action | P10: mc:m:motor:XXX:quitError_W | R10: 22 | S10: MC_M_M_W | V10: Motor status | W10: Byte Monitor | X10: Read | Y10: mc:m:motor:xxx:motorStatus_R | AA10: 212 | AB10: MC_M_M_R
C11: Desired Position | D11: Text Update | E11: Action | F11: mc:m:motor:XXX:desiredPosition_W | H11: 24 | I11: MC_M_M_W | M11: Desired Position | N11: Text Update | O11: Action | P11: mc:m:motor:XXX:desiredPosition_W | R11: 24 | S11: MC_M_M_W | U11: Motor 2 | V11: Motor position | W11: Text entry | X11: Read | Y11: mc:m:motor:XXX:ActPosition_R | Z11: _LMCAxis_M1.ActPos | AA11: 214 | AB11: MC_M_M_R
C12: Home Forward | D12: Action | E12: Action | F12: mc:m:motor:XXX:Home:forward_W | H12: 26 | I12: MC_M_M_W | M12: Home Forward | N12: Action | O12: Action | P12: mc:m:motor:XXX:Home:forward_W | R12: 26 | S12: MC_M_M_W | V12: Error | W12: LED | X12: Read | Y12: mc:m:motor:XXX:Error_R | AA12: 216 | AB12: MC_M_M_R
C13: Home Reverse | D13: Action | E13: Action | F13: mc:m:motor:XXX:Home:reverse_W | H13: 28 | I13: MC_M_M_W | M13: Home Reverse | N13: Action | O13: Action | P13: mc:m:motor:XXX:Home:reverse_W | R13: 28 | S13: MC_M_M_W | V13: Forward in position | W13: LED | X13: Read | Y13: mc:m:motor:XXX:Forward:inPosition_R | AA13: 218 | AB13: MC_M_M_R
C14: Reverse per step | D14: Action | E14: Action | F14: mc:m:motor:XXX:Reverse:perStep_W | H14: 30 | I14: MC_M_M_W | M14: Reverse per step | N14: Action | O14: Action | P14: mc:m:motor:XXX:Reverse:perStep_W | R14: 30 | S14: MC_M_M_W | V14: Reverse in position | W14: LED | X14: Read | Y14: mc:m:motor:XXX:Reverse:inPosition_R | AA14: 220 | AB14: MC_M_M_R
C15: Forward per step | D15: Action | E15: Action | F15: mc:m:motor:XXX:Forward:perStep_W | H15: 32 | I15: MC_M_M_W | M15: Forward per step | N15: Action | O15: Action | P15: mc:m:motor:XXX:Forward:perStep_W | R15: 32 | S15: MC_M_M_W | V15: Maximum settable speed | W15: Text Update | X15: Read | Y15: mc:m:motor:XXX:MaxSpeed_R | AA15: 222 | AB15: MC_M_M_R
C16: Motor position | D16: Text entry | E16: Read | F16: mc:m:motor:XXX:ActPosition_R | G16: _LMCAxis_M1.ActPos | H16: 34 | I16: MC_M_M_R | L16: Motor 2 | M16: Power On | N16: Action | O16: Action | P16: mc:m:motor:XXX:powerOn_W | R16: 34 | S16: MC_M_M_W | V16: Minimum settable speed | W16: Text Update | X16: Read | Y16: mc:m:motor:XXX:MinSpeed_R | AA16: 224 | AB16: MC_M_M_R
C17: Error | D17: LED | E17: Read | F17: mc:m:motor:XXX:Error_R | H17: 36 | I17: MC_M_M_R | M17: Power Off | N17: Action | O17: Action | P17: mc:m:motor:XXX:powerOff_W | R17: 36 | S17: MC_M_M_W | V17: Motor status | W17: Byte Monitor | X17: Read | Y17: mc:m:motor:xxx:motorStatus_R | AA17: 226 | AB17: MC_M_M_R
C18: Forward in position | D18: LED | E18: Read | F18: mc:m:motor:XXX:Forward:inPosition_R | H18: 38 | I18: MC_M_M_R | M18: Setting speed | N18: Spinner | O18: Action | P18: mc:m:motor:XXX:speed_W | R18: 38 | S18: MC_M_M_W | U18: Motor 3 | V18: Motor position | W18: Text entry | X18: Read | Y18: mc:m:motor:XXX:ActPosition_R | Z18: _LMCAxis_M1.ActPos | AA18: 228 | AB18: MC_M_M_R
C19: Reverse in position | D19: LED | E19: Read | F19: mc:m:motor:XXX:Reverse:inPosition_R | H19: 40 | I19: MC_M_M_R | M19: Start Movement | N19: Action | O19: Action | P19: mc:m:motor:XXX:start_W | R19: 40 | S19: MC_M_M_W | V19: Error | W19: LED | X19: Read | Y19: mc:m:motor:XXX:Error_R | AA19: 230 | AB19: MC_M_M_R
C20: Maximum settable speed | D20: Text Update | E20: Read | F20: mc:m:motor:XXX:MaxSpeed_R | H20: 42 | I20: MC_M_M_R | M20: Motor stop | N20: Action | O20: Action | P20: mc:m:motor:XXX:stop_W | R20: 42 | S20: MC_M_M_W | V20: Forward in position | W20: LED | X20: Read | Y20: mc:m:motor:XXX:Forward:inPosition_R | AA20: 232 | AB20: MC_M_M_R
C21: Minimum settable speed | D21: Text Update | E21: Read | F21: mc:m:motor:XXX:MinSpeed_R | H21: 44 | I21: MC_M_M_R | M21: Direction | N21: Boolean | O21: Action | P21: mc:m:motor:XXX:direction_W | R21: 44 | S21: MC_M_M_W | V21: Reverse in position | W21: LED | X21: Read | Y21: mc:m:motor:XXX:Reverse:inPosition_R | AA21: 234 | AB21: MC_M_M_R
C22: Motor status | D22: Byte Monitor | E22: Read | F22: mc:m:motor:xxx:motorStatus_R | H22: 46 | I22: MC_M_M_R | M22: Reset errors | N22: Action | O22: Action | P22: mc:m:motor:XXX:quitError_W | R22: 46 | S22: MC_M_M_W | V22: Maximum settable speed | W22: Text Update | X22: Read | Y22: mc:m:motor:XXX:MaxSpeed_R | AA22: 236 | AB22: MC_M_M_R
B23: Motor 2 | C23: Power On | D23: Action | E23: Action | F23: mc:m:motor:XXX:powerOn_W | H23: 48 | I23: MC_M_M_W | M23: Desired Position | N23: Text Update | O23: Action | P23: mc:m:motor:XXX:desiredPosition_W | R23: 48 | S23: MC_M_M_W | V23: Minimum settable speed | W23: Text Update | X23: Read | Y23: mc:m:motor:XXX:MinSpeed_R | AA23: 238 | AB23: MC_M_M_R
C24: Power Off | D24: Action | E24: Action | F24: mc:m:motor:XXX:powerOff_W | H24: 50 | I24: MC_M_M_W | M24: Home Forward | N24: Action | O24: Action | P24: mc:m:motor:XXX:Home:forward_W | R24: 50 | S24: MC_M_M_W | V24: Motor status | W24: Byte Monitor | X24: Read | Y24: mc:m:motor:xxx:motorStatus_R | AA24: 240 | AB24: MC_M_M_R
C25: Setting speed | D25: Spinner | E25: Action | F25: mc:m:motor:XXX:speed_W | H25: 52 | I25: MC_M_M_W | M25: Home Reverse | N25: Action | O25: Action | P25: mc:m:motor:XXX:Home:reverse_W | R25: 52 | S25: MC_M_M_W | U25: Motor 4 | V25: Motor position | W25: Text entry | X25: Read | Y25: mc:m:motor:XXX:ActPosition_R | Z25: _LMCAxis_M1.ActPos | AA25: 242 | AB25: MC_M_M_R
C26: Start Movement | D26: Action | E26: Action | F26: mc:m:motor:XXX:start_W | H26: 54 | I26: MC_M_M_W | M26: Reverse per step | N26: Action | O26: Action | P26: mc:m:motor:XXX:Reverse:perStep_W | R26: 54 | S26: MC_M_M_W | V26: Error | W26: LED | X26: Read | Y26: mc:m:motor:XXX:Error_R | AA26: 244 | AB26: MC_M_M_R
C27: Motor stop | D27: Action | E27: Action | F27: mc:m:motor:XXX:stop_W | H27: 56 | I27: MC_M_M_W | M27: Forward per step | N27: Action | O27: Action | P27: mc:m:motor:XXX:Forward:perStep_W | R27: 56 | S27: MC_M_M_W | V27: Forward in position | W27: LED | X27: Read | Y27: mc:m:motor:XXX:Forward:inPosition_R | AA27: 246 | AB27: MC_M_M_R
C28: Direction | D28: Boolean | E28: Action | F28: mc:m:motor:XXX:direction_W | H28: 58 | I28: MC_M_M_W | L28: Motor 3 | M28: Power On | N28: Action | O28: Action | P28: mc:m:motor:XXX:powerOn_W | R28: 58 | S28: MC_M_M_W | V28: Reverse in position | W28: LED | X28: Read | Y28: mc:m:motor:XXX:Reverse:inPosition_R | AA28: 248 | AB28: MC_M_M_R
C29: Reset errors | D29: Action | E29: Action | F29: mc:m:motor:XXX:quitError_W | H29: 60 | I29: MC_M_M_W | M29: Power Off | N29: Action | O29: Action | P29: mc:m:motor:XXX:powerOff_W | R29: 60 | S29: MC_M_M_W | V29: Maximum settable speed | W29: Text Update | X29: Read | Y29: mc:m:motor:XXX:MaxSpeed_R | AA29: 250 | AB29: MC_M_M_R
C30: Desired Position | D30: Text Update | E30: Action | F30: mc:m:motor:XXX:desiredPosition_W | H30: 62 | I30: MC_M_M_W | M30: Setting speed | N30: Spinner | O30: Action | P30: mc:m:motor:XXX:speed_W | R30: 62 | S30: MC_M_M_W | V30: Minimum settable speed | W30: Text Update | X30: Read | Y30: mc:m:motor:XXX:MinSpeed_R | AA30: 252 | AB30: MC_M_M_R
C31: Home Forward | D31: Action | E31: Action | F31: mc:m:motor:XXX:Home:forward_W | H31: 64 | I31: MC_M_M_W | M31: Start Movement | N31: Action | O31: Action | P31: mc:m:motor:XXX:start_W | R31: 64 | S31: MC_M_M_W | V31: Motor status | W31: Byte Monitor | X31: Read | Y31: mc:m:motor:xxx:motorStatus_R | AA31: 254 | AB31: MC_M_M_R
C32: Home Reverse | D32: Action | E32: Action | F32: mc:m:motor:XXX:Home:reverse_W | H32: 66 | I32: MC_M_M_W | M32: Motor stop | N32: Action | O32: Action | P32: mc:m:motor:XXX:stop_W | R32: 66 | S32: MC_M_M_W | U32: Motor 5 | V32: Motor position | W32: Text entry | X32: Read | Y32: mc:m:motor:XXX:ActPosition_R | Z32: _LMCAxis_M1.ActPos | AA32: 256 | AB32: MC_M_M_R
C33: Reverse per step | D33: Action | E33: Action | F33: mc:m:motor:XXX:Reverse:perStep_W | H33: 68 | I33: MC_M_M_W | M33: Direction | N33: Boolean | O33: Action | P33: mc:m:motor:XXX:direction_W | R33: 68 | S33: MC_M_M_W | V33: Error | W33: LED | X33: Read | Y33: mc:m:motor:XXX:Error_R | AA33: 258 | AB33: MC_M_M_R
C34: Forward per step | D34: Action | E34: Action | F34: mc:m:motor:XXX:Forward:perStep_W | H34: 70 | I34: MC_M_M_W | M34: Reset errors | N34: Action | O34: Action | P34: mc:m:motor:XXX:quitError_W | R34: 70 | S34: MC_M_M_W | V34: Forward in position | W34: LED | X34: Read | Y34: mc:m:motor:XXX:Forward:inPosition_R | AA34: 260 | AB34: MC_M_M_R
C35: Motor position | D35: Text entry | E35: Read | F35: mc:m:motor:XXX:ActPosition_R | G35: _LMCAxis_M1.ActPos | H35: 72 | I35: MC_M_M_R | M35: Desired Position | N35: Text Update | O35: Action | P35: mc:m:motor:XXX:desiredPosition_W | R35: 72 | S35: MC_M_M_W | V35: Reverse in position | W35: LED | X35: Read | Y35: mc:m:motor:XXX:Reverse:inPosition_R | AA35: 262 | AB35: MC_M_M_R
C36: Error | D36: LED | E36: Read | F36: mc:m:motor:XXX:Error_R | H36: 74 | I36: MC_M_M_R | M36: Home Forward | N36: Action | O36: Action | P36: mc:m:motor:XXX:Home:forward_W | R36: 74 | S36: MC_M_M_W | V36: Maximum settable speed | W36: Text Update | X36: Read | Y36: mc:m:motor:XXX:MaxSpeed_R | AA36: 264 | AB36: MC_M_M_R
C37: Forward in position | D37: LED | E37: Read | F37: mc:m:motor:XXX:Forward:inPosition_R | H37: 76 | I37: MC_M_M_R | M37: Home Reverse | N37: Action | O37: Action | P37: mc:m:motor:XXX:Home:reverse_W | R37: 76 | S37: MC_M_M_W | V37: Minimum settable speed | W37: Text Update | X37: Read | Y37: mc:m:motor:XXX:MinSpeed_R | AA37: 266 | AB37: MC_M_M_R
C38: Reverse in position | D38: LED | E38: Read | F38: mc:m:motor:XXX:Reverse:inPosition_R | H38: 78 | I38: MC_M_M_R | M38: Reverse per step | N38: Action | O38: Action | P38: mc:m:motor:XXX:Reverse:perStep_W | R38: 78 | S38: MC_M_M_W | V38: Motor status | W38: Byte Monitor | X38: Read | Y38: mc:m:motor:xxx:motorStatus_R | AA38: 268 | AB38: MC_M_M_R
C39: Maximum settable speed | D39: Text Update | E39: Read | F39: mc:m:motor:XXX:MaxSpeed_R | H39: 80 | I39: MC_M_M_R | M39: Forward per step | N39: Action | O39: Action | P39: mc:m:motor:XXX:Forward:perStep_W | R39: 80 | S39: MC_M_M_W | U39: Motor 6 | V39: Motor position | W39: Text entry | X39: Read | Y39: mc:m:motor:XXX:ActPosition_R | Z39: _LMCAxis_M1.ActPos | AA39: 270 | AB39: MC_M_M_R
C40: Minimum settable speed | D40: Text Update | E40: Read | F40: mc:m:motor:XXX:MinSpeed_R | H40: 82 | I40: MC_M_M_R | L40: Motor 4 | M40: Power On | N40: Action | O40: Action | P40: mc:m:motor:XXX:powerOn_W | R40: 82 | S40: MC_M_M_W | V40: Error | W40: LED | X40: Read | Y40: mc:m:motor:XXX:Error_R | AA40: 272 | AB40: MC_M_M_R
C41: Motor status | D41: Byte Monitor | E41: Read | H41: 84 | I41: MC_M_M_R | M41: Power Off | N41: Action | O41: Action | P41: mc:m:motor:XXX:powerOff_W | R41: 84 | S41: MC_M_M_W | V41: Forward in position | W41: LED | X41: Read | Y41: mc:m:motor:XXX:Forward:inPosition_R | AA41: 274 | AB41: MC_M_M_R
B42: Motor 3 | C42: Power On | D42: Action | E42: Action | F42: mc:m:motor:XXX:powerOn_W | H42: 86 | I42: MC_M_M_W | M42: Setting speed | N42: Spinner | O42: Action | P42: mc:m:motor:XXX:speed_W | R42: 86 | S42: MC_M_M_W | V42: Reverse in position | W42: LED | X42: Read | Y42: mc:m:motor:XXX:Reverse:inPosition_R | AA42: 276 | AB42: MC_M_M_R
...

Sheet Motion control-manual-solenoids
A2: GUI section | B2: Function description | C2: Button type | D2: Type | E2: EPICS Variable (PVs) | F2: PLC Variable | G2: Modbus addresses | H2: PLC port name
A3: Motion control - manual - solenoids | B3: Lock 1 extract | C3: Action | D3: Action | E3: mc:m:solenoid:lock:1:extract_W | G3: 320 | H3: MC_M_S_W
B4: Lock 1 insert | C4: Action | D4: Action
B5: Lock 2 extract | C5: Action | D5: Action | E5: mc:m:solenoid:lock:2:extract_W | G5: 322 | H5: MC_M_S_W
B6: Lock 2 insert | C6: Action | D6: Action
B7: Lock 1 extracted | C7: LED | D7: Read | E7: mc:m:solenoid:lock:1:extracted_R | G7: 320 | H7: MC_M_S_R
B8: Lock 1 inserted | C8: LED | D8: Read
B9: Lock 2 extracted | C9: LED | D9: Read | E9: mc:m:solenoid:lock:2:extracted_R | G9: 322 | H9: MC_M_S_R
B10: Lock 2 inserted | C10: LED | D10: Read

Sheet Motion control-automatic-mc
A2: GUI section | B2: Function description | C2: Button type | D2: Type | E2: EPICS Variable (PVs) | F2: PLC Variable | G2: Modbus addresses | H2: PLC port name | I2: note
A3: Motion control - automatic - main control | B3: Rack 12V On/Off | C3: Slider | D3: Action | E3: mc:a:maincontrol:CommantRack12V_W | G3: 348 | H3: MC_A_MC_W
B4: Home (Start) | C4: Action Button | D4: Action | E4: mc:a:maincontrol:generalControl_W | G4: 350 | H4: MC_A_MC_W
B5: Charge | C5: Action Button | D5: Action
B6: Irradiation | C6: Action Button | D6: Action
B7: Discharge | C7: Action Button | D7: Action
B8: Irradiation start | C8: Boolean Button | D8: Action | E8: mc:a:maincontrol:irradiationControl_W | G8: 352 | H8: MC_A_MC_W
B9: Irradiation over | C9: Boolean Button | D9: Action
B10: Measurement start | C10: Boolean Button | D10: Action | E10: mc:a:maincontrol:measurementControl_W | G10: 354 | H10: MC_A_MC_W
B11: Measurement over | C11: Boolean Button | D11: Action
B12: MPS request - decouple | C12: Boolean Button | D12: Action | E12: mc:a:maincontrol:MPS:ReqDecouple_W | G12: 356 | H12: MC_A_MC_W
B13: M3_Recouple | C13: Action Button | D13: Action | E13: mc:a:maincontrol:RecoupleM3_W | G13: 358 | H13: MC_A_MC_W
B14: Auto/Man selector | C14: Action Button | D14: Action | E14: mc:a:maincontrol:AutoManSelector_W | G14: 360 | H14: MC_A_MC_W
B15: Emergency stop button | C15: Action Button | D15: Action | E15: mc:a:maincontrol:StopButton_W | G15: 362 | H15: MC_A_MC_W
B16: Auto/Man selector | C16: LED | D16: Read | E16: mc:a:maincontrol:AutoManSelector_R | G16: 364 | H16: MC_A_MC_R
B17: Tablet 1 irradiation | C17: LED | D17: Read | E17: mc:a:maincontrol:tablet:irradiation_R | G17: 366 | H17: MC_A_MC_R
B18: Tablet 2 irradiation | C18: LED | D18: Read
B19: Tablet 3 irradiation | C19: LED | D19: Read
B20: Tablet 1 discharge | C20: LED | D20: Read | E20: mc:a:maincontrol:Tablet:discharge_R | G20: 368 | H20: MC_A_MC_R
B21: Tablet 2 discharge | C21: LED | D21: Read
B22: Tablet 3 discharge | C22: LED | D22: Read
B23: Home state | C23: LED (Multi State) | D23: Read | E23: mc:a:maincontrol:home_R | G23: 370 | H23: MC_A_MC_R | I23: All motors homed
B24: Charge state | C24: LED (Multi State) | D24: Read | E24: mc:a:maincontrol:Charge_R | G24: 372 | H24: MC_A_MC_R | I24: All tablets charged
B25: Discharge state | C25: LED (Multi State) | D25: Read | E25: mc:a:maincontrol:Discharge_R | G25: 374 | H25: MC_A_MC_R | I25: All tablet in discharge slider
B26: Comando generale | C26: LED (Multi State) | D26: Read | E26: mc:a:maincontrol:generalControl_R | G26: 376 | H26: MC_A_MC_R
B27: Tablet in Irradiation Position | C27: LED | D27: Read | E27: mc:a:maincontrol:tablet_In_Irr_Pos_R | G27: 378 | H27: MC_A_MC_R
B28: MPS ACK | C28: LED | D28: Read | E28: mc:a:maincontrol:MPS_ACK_R | G28: 380 | H28: MC_A_MC_R
B31: Irradiation | C31: LED (Multi State) | D31: Read | E31: mc:a:maincontrol:coupled_R | G31: 570
B32: Decoupled (m6) | C32: LED | D32: Read | E32: mc:a:maincontrol:Decoupled_R | G32: 570
B33: Charge slider state | C33: LED (Multi State) | D33: Read | E33: mc:a:maincontrol:ChargeSlider_R | G33: 544 | I33: coupled/decoupled
B34: Discharge slider state | C34: LED (Multi State) | D34: Read | E34: mc:a:maincontrol:DischargeSlider_R | G34: 556 | I34: coupled/decoupled
B36: MPS state - irradiation | C36: LED (Multi State) | D36: Read | F36: Variable provided by MPS
B37: MPS state - decouple | C37: LED (Multi State) | D37: Read | F37: Variable provided by MPS
B38: Vacuum - pressure | C38: Text Update | D38: Read | F38: Variable provided by SPES
B39: Faraday cup read value | C39: Text Update | D39: Read | F39: Variable provided by MPS
B40: Collimator read value | C40: Text Update | D40: Read | F40: Variable provided by MPS
B41: MPS request - irradiation (vacuum?) | C41: Boolean Button | D41: Action | E41: mc:a:maincontrol:MPS:ReqIrradiation_W | F41: Variable provided by SPES
B42: Collimator extract | C42: Boolean Button | D42: Action | E42: mc:a:maincontrol:collimator:extract_W | F42: Variable provided by SPES
B45: Set Irradiation Timer 1 | C45: Text Update | D45: Action | E45: mc:a:maincontrol:Timer1_W | G45: 600 | H45: MC_A_MC_W_2
B46: Set Irradiation Timer 2 | C46: Text Update | D46: Action | E46: mc:a:maincontrol:Timer2_W | G46: 602 | H46: MC_A_MC_W_2
...

Sheet MotionControl-automatic-stepSet
A2: GUI section | C2: Function description | D2: Button type | E2: Type | F2: EPICS Variable (PVs) | G2: PLC Variable | H2: Modbus addresses | I2: PLC port name
A3: MotionControl-automatic-stepSet | C3: M1 correction step | D3: Spinner | E3: Action | F3: mc:a:stepSetting:motor:1:CorrectionStep_W | H3: 500 | I3: MC_A_S_W
C4: M3 correction step | D4: Spinner | E4: Action | F4: mc:a:stepSetting:motor:3:CorrectionStep_W | H4: 502 | I4: MC_A_S_W
C5: M4 Offset Step | D5: Spinner | E5: Action | F5: mc:a:stepSetting:motor:4:OffsetStep_W | H5: 504 | I5: MC_A_S_W
C6: M5 charging correction step 1 | D6: Spinner | E6: Action | F6: mc:a:stepSetting:motor:5:chargingCorrectionStep:1_W | H6: 506 | I6: MC_A_S_W
C7: M5 charging correction step 2 | D7: Spinner | E7: Action | F7: mc:a:stepSetting:motor:5:chargingCorrectionStep:2_W | H7: 508 | I7: MC_A_S_W
C8: M5 charging correction step 3 | D8: Spinner | E8: Action | F8: mc:a:stepSetting:motor:5:chargingCorrectionStep:3_W | H8: 510 | I8: MC_A_S_W
C9: M5 irradiation correction step 1 | D9: Spinner | E9: Action | F9: mc:a:stepSetting:motor:5:IrradiationCorrectionStep:1_W | H9: 512 | I9: MC_A_S_W
C10: M5 irradiation correction step 2 | D10: Spinner | E10: Action | F10: mc:a:stepSetting:motor:5:IrradiationCorrectionStep:2_W | H10: 514 | I10: MC_A_S_W
C11: M5 irradiation correction step 3 | D11: Spinner | E11: Action | F11: mc:a:stepSetting:motor:5:IrradiationCorrectionStep:3_W | H11: 516 | I11: MC_A_S_W
C12: M5 discharging correction step | D12: Spinner | E12: Action | F12: mc:a:stepSetting:motor:5:DischargingCorrectionStep_W | H12: 518 | I12: MC_A_S_W
C13: M5 discharging step 3 | D13: Text Update | E13: Read | F13: mc:a:stepSetting:motor:5:OffsetDischarge_W | I13: MC_A_S_W
C14: M1 moving step | D14: Text Update | E14: Read | F14: mc:a:stepSetting:motor:1:ExactStep_R | H14: 520 | I14: MC_A_S_R
C15: M3 moving step | D15: Text Update | E15: Read | F15: mc:a:stepSetting:motor:3:ExactStep_R | H15: 522 | I15: MC_A_S_R
C16: M4 Moving Step | D16: Text Update | E16: Read | F16: mc:a:stepSetting:motor:4:ExactStep_R | H16: 524 | I16: MC_A_S_R
C17: M5 charging step 1 | D17: Text Update | E17: Read | F17: mc:a:stepSetting:motor:5:chargingStep:1_R | H17: 526 | I17: MC_A_S_R
C18: M5 charging step 2 | D18: Text Update | E18: Read | F18: mc:a:stepSetting:motor:5:chargingStep:2_R | H18: 528 | I18: MC_A_S_R
C19: M5 charging step 3 | D19: Text Update | E19: Read | F19: mc:a:stepSetting:motor:5:chargingStep:3_R | H19: 530 | I19: MC_A_S_R
C20: M5 irradiation step 1 | D20: Text Update | E20: Read | F20: mc:a:stepSetting:motor:5:IrradiationStep:1_R | H20: 532 | I20: MC_A_S_R
C21: M5 irradiation step 2 | D21: Text Update | E21: Read | F21: mc:a:stepSetting:motor:5:IrradiationStep:2_R | H21: 534 | I21: MC_A_S_R
C22: M5 irradiation step 3 | D22: Text Update | E22: Read | F22: mc:a:stepSetting:motor:5:IrradiationStep:3_R | H22: 536 | I22: MC_A_S_R
C23: M5 discharging step 1 | D23: Text Update | E23: Read | F23: mc:a:stepSetting:motor:5:DischargingStep_R | H23: 538 | I23: MC_A_S_R
C24: M5 discharging step 2 | D24: Text Update | E24: Read | F24: mc:a:stepSetting:motor:5:OffsetDischarge_R | H24: 540 | I24: MC_A_S_R
B26: M1 | C26: Motor power state | D26: LED | E26: Read | F26: mc:a:stepSetting:Motor:xxx:state_R, bit 0 | H26: 542 | I26: MC_A_S_R | J26: part of state word
C27: Motor in movement | D27: LED | E27: Read | F27: mc:a:stepSetting:Motor:xxx:state_R, bit 25 | J27: part of state word
C28: Motor coupled | D28: LED | E28: Read | F28: mc:a:stepSetting:Motor:xxx:Coupled_R | H28: 544 | I28: MC_A_S_R
C29: Motor home state | D29: LED | E29: Read | F29: mc:a:stepSetting:Motor:xxx:home:state_R | H29: 546 | I29: MC_A_S_R
B30: M2 | C30: Motor power state | D30: LED | E30: Read | F30: mc:a:stepSetting:Motor:xxx:state_R, bit 0 | H30: 548 | I30: MC_A_S_R | J30: part of state word
C31: Motor in movement | D31: LED | E31: Read | F31: mc:a:stepSetting:Motor:xxx:state_R, bit 25 | I31: MC_A_S_R | J31: part of state word
C32: Motor home state | D32: LED | E32: Read | F32: mc:a:stepSetting:Motor:xxx:home:state_R | H32: 550 | I32: MC_A_S_R
B33: M3 | C33: Motor power state | D33: LED | E33: Read | F33: mc:a:stepSetting:Motor:xxx:state_R, bit 0 | H33: 552 | I33: MC_A_S_R | J33: part of state word
C34: Motor in movement | D34: LED | E34: Read | F34: mc:a:stepSetting:Motor:xxx:state_R, bit 25 | I34: MC_A_S_R | J34: part of state word
C35: Motor coupled | D35: LED | E35: Read | F35: mc:a:stepSetting:Motor:xxx:Coupled_R | H35: 554 | I35: MC_A_S_R
C36: Motor home state | D36: LED | E36: Read | F36: mc:a:stepSetting:Motor:xxx:home:state_R | H36: 556 | I36: MC_A_S_R
B37: M4 | C37: Motor power state | D37: LED | E37: Read | F37: mc:a:stepSetting:Motor:xxx:state_R, bit 0 | H37: 558 | I37: MC_A_S_R | J37: part of state word
C38: Motor in movement | D38: LED | E38: Read | F38: mc:a:stepSetting:Motor:xxx:state_R, bit 25 | I38: MC_A_S_R | J38: part of state word
C39: Motor home state | D39: LED | E39: Read | F39: mc:a:stepSetting:Motor:xxx:home:state_R | H39: 560 | I39: MC_A_S_R
B40: M5 | C40: Motor power state | D40: LED | E40: Read | F40: mc:a:stepSetting:Motor:xxx:state_R, bit 0 | H40: 562 | I40: MC_A_S_R | J40: part of state word
C41: Motor in movement | D41: LED | E41: Read | F41: mc:a:stepSetting:Motor:xxx:state_R, bit 25 | I41: MC_A_S_R | J41: part of state word
C42: Motor home state | D42: LED | E42: Read | F42: mc:a:stepSetting:Motor:xxx:home:state_R | H42: 564 | I42: MC_A_S_R
...

Sheet Sheet2
C3: Function description | D3: Button type | E3: Type | F3: EPICS Variable (PVs) | G3: PLC Variable | H3: Modbus Addresses | I3: plc port name
B4: Motor 1 | C4: Power On | D4: Action | E4: Action | F4: mc:m:motor:XXX:powerOn_W | H4: 10 | I4: MC_M_M_W
C5: Power Off | D5: Action | E5: Action | F5: mc:m:motor:XXX:powerOff_W | H5: 12 | I5: MC_M_M_W
C6: Setting speed | D6: Spinner | E6: Action | F6: mc:m:motor:XXX:speed_W | H6: 14 | I6: MC_M_M_W
C7: Start Movement | D7: Action | E7: Action | F7: mc:m:motor:XXX:start_W | H7: 16 | I7: MC_M_M_W
C8: Motor stop | D8: Action | E8: Action | F8: mc:m:motor:XXX:stop_W | H8: 18 | I8: MC_M_M_W
C9: Direction | D9: Boolean | E9: Action | F9: mc:m:motor:XXX:direction_W | H9: 20 | I9: MC_M_M_W
C10: Reset errors | D10: Action | E10: Action | F10: mc:m:motor:XXX:quitError_W | H10: 22 | I10: MC_M_M_W
C11: Desired Position | D11: Text Update | E11: Action | F11: mc:m:motor:XXX:desiredPosition_W | H11: 24 | I11: MC_M_M_W
C12: Home Forward | D12: Action | E12: Action | F12: mc:m:motor:XXX:Home:forward_W | H12: 26 | I12: MC_M_M_W
C13: Home Reverse | D13: Action | E13: Action | F13: mc:m:motor:XXX:Home:reverse_W | H13: 28 | I13: MC_M_M_W
C14: Reverse per step | D14: Action | E14: Action | F14: mc:m:motor:XXX:Reverse:perStep_W | H14: 30 | I14: MC_M_M_W
C15: Forward per step | D15: Action | E15: Action | F15: mc:m:motor:XXX:Forward:perStep_W | H15: 32 | I15: MC_M_M_W
B16: Motor 2 | C16: Power On | D16: Action | E16: Action | F16: mc:m:motor:XXX:powerOn_W | H16: 34 | I16: MC_M_M_W
C17: Power Off | D17: Action | E17: Action | F17: mc:m:motor:XXX:powerOff_W | H17: 36 | I17: MC_M_M_W
C18: Setting speed | D18: Spinner | E18: Action | F18: mc:m:motor:XXX:speed_W | H18: 38 | I18: MC_M_M_W
C19: Start Movement | D19: Action | E19: Action | F19: mc:m:motor:XXX:start_W | H19: 40 | I19: MC_M_M_W
C20: Motor stop | D20: Action | E20: Action | F20: mc:m:motor:XXX:stop_W | H20: 42 | I20: MC_M_M_W
C21: Direction | D21: Boolean | E21: Action | F21: mc:m:motor:XXX:direction_W | H21: 44 | I21: MC_M_M_W
C22: Reset errors | D22: Action | E22: Action | F22: mc:m:motor:XXX:quitError_W | H22: 46 | I22: MC_M_M_W
C23: Desired Position | D23: Text Update | E23: Action | F23: mc:m:motor:XXX:desiredPosition_W | H23: 48 | I23: MC_M_M_W
C24: Home Forward | D24: Action | E24: Action | F24: mc:m:motor:XXX:Home:forward_W | H24: 50 | I24: MC_M_M_W
C25: Home Reverse | D25: Action | E25: Action | F25: mc:m:motor:XXX:Home:reverse_W | H25: 52 | I25: MC_M_M_W
C26: Reverse per step | D26: Action | E26: Action | F26: mc:m:motor:XXX:Reverse:perStep_W | H26: 54 | I26: MC_M_M_W
C27: Forward per step | D27: Action | E27: Action | F27: mc:m:motor:XXX:Forward:perStep_W | H27: 56 | I27: MC_M_M_W
B28: Motor 3 | C28: Power On | D28: Action | E28: Action | F28: mc:m:motor:XXX:powerOn_W | H28: 58 | I28: MC_M_M_W
C29: Power Off | D29: Action | E29: Action | F29: mc:m:motor:XXX:powerOff_W | H29: 60 | I29: MC_M_M_W
C30: Setting speed | D30: Spinner | E30: Action | F30: mc:m:motor:XXX:speed_W | H30: 62 | I30: MC_M_M_W
C31: Start Movement | D31: Action | E31: Action | F31: mc:m:motor:XXX:start_W | H31: 64 | I31: MC_M_M_W
C32: Motor stop | D32: Action | E32: Action | F32: mc:m:motor:XXX:stop_W | H32: 66 | I32: MC_M_M_W
C33: Direction | D33: Boolean | E33: Action | F33: mc:m:motor:XXX:direction_W | H33: 68 | I33: MC_M_M_W
C34: Reset errors | D34: Action | E34: Action | F34: mc:m:motor:XXX:quitError_W | H34: 70 | I34: MC_M_M_W
C35: Desired Position | D35: Text Update | E35: Action | F35: mc:m:motor:XXX:desiredPosition_W | H35: 72 | I35: MC_M_M_W
C36: Home Forward | D36: Action | E36: Action | F36: mc:m:motor:XXX:Home:forward_W | H36: 74 | I36: MC_M_M_W
C37: Home Reverse | D37: Action | E37: Action | F37: mc:m:motor:XXX:Home:reverse_W | H37: 76 | I37: MC_M_M_W
C38: Reverse per step | D38: Action | E38: Action | F38: mc:m:motor:XXX:Reverse:perStep_W | H38: 78 | I38: MC_M_M_W
C39: Forward per step | D39: Action | E39: Action | F39: mc:m:motor:XXX:Forward:perStep_W | H39: 80 | I39: MC_M_M_W
B40: Motor 4 | C40: Power On | D40: Action | E40: Action | F40: mc:m:motor:XXX:powerOn_W | H40: 82 | I40: MC_M_M_W
C41: Power Off | D41: Action | E41: Action | F41: mc:m:motor:XXX:powerOff_W | H41: 84 | I41: MC_M_M_W
C42: Setting speed | D42: Spinner | E42: Action | F42: mc:m:motor:XXX:speed_W | H42: 86 | I42: MC_M_M_W
...

Sheet AutoSaving
C2: when EPICS ioc shuts down does the motors remain in position? | I2: Sì perchè è il PLC che "comanda"
C3: Yes -> save also that variables, No -> not necessary
C4: Regarding a pv that is present both in read and write versions, which one should we save? Both? | K4: Solo quelle write perchè le read sono "indipendenti" da epics
B6: General | C6: =General!E63 -> mc:a:stepSetting:motor:1:movingStep_W
C7: =General!E64 -> mc:a:stepSetting:motor:1:CorrectionStep_W
C8: =General!E65 -> mc:a:stepSetting:motor:3:movingStep_W
C9: =General!E66 -> mc:a:stepSetting:motor:3:CorrectionStep_W
C10: =General!E67 -> mc:a:stepSetting:motor:5:chargingStep:1_W
C11: =General!E68 -> mc:a:stepSetting:motor:5:chargingStep:2_W
C12: =General!E69 -> mc:a:stepSetting:motor:5:chargingStep:3_W
C13: =General!E70 -> mc:a:stepSetting:motor:5:IrradiationStep:1_W
C14: =General!E71 -> mc:a:stepSetting:motor:5:IrradiationStep:2_W
C15: =General!E72 -> mc:a:stepSetting:motor:5:IrradiationStep:3_W
C16: =General!E73 -> mc:a:stepSetting:motor:5:DischargingStep:1_W
C17: =General!E74 -> mc:a:stepSetting:motor:5:DischargingStep:2_W
C18: =General!E75 -> mc:a:stepSetting:motor:5:DischargingStep:3_W
B20: General_Update | C20: =General_Update!F52 -> mc:a:maincontrol:coupled_W
C21: =General_Update!F53 -> mc:a:maincontrol:MPS:ReqIrradiation_W
C22: =General_Update!F54 -> mc:a:maincontrol:collimator:extract_W
C23: =General_Update!F55 -> mc:a:maincontrol:IrradiationControl_W
C25: =General_Update!F57 -> mc:a:maincontrol:Tablet:Irradiation:1_R
C26: =General_Update!F58 -> mc:a:maincontrol:Tablet:Irradiation:2_R
C27: =General_Update!F59 -> mc:a:maincontrol:Tablet:Irradiation:3_R
C28: =General_Update!F60 -> mc:a:maincontrol:MPS:ReqDecouple_W
C29: =General_Update!F61 -> mc:a:maincontrol:Decoupled_R
C30: =General_Update!F62 -> mc:a:maincontrol:MeasurementControl_W
B32: Motion control-manual - motor X | C32: none
B34: Motion control-manual-solenoids | C34: none
B36: Motion control-automatic-mc | C36: ='Motion control-automatic-mc'!E4 -> mc:a:maincontrol:generalControl_W
C37: ='Motion control-automatic-mc'!E31 -> mc:a:maincontrol:coupled_R
C38: ='Motion control-automatic-mc'!E41 -> mc:a:maincontrol:MPS:ReqIrradiation_W
C39: ='Motion control-automatic-mc'!E42 -> mc:a:maincontrol:collimator:extract_W
B41: MotionControl-automatic-stepSet | C41: ='MotionControl-automatic-stepSet'!F3 -> mc:a:stepSetting:motor:1:CorrectionStep_W
C42: ='MotionControl-automatic-stepSet'!F4 -> mc:a:stepSetting:motor:3:CorrectionStep_W
C43: ='MotionControl-automatic-stepSet'!F5 -> mc:a:stepSetting:motor:4:OffsetStep_W
C44: ='MotionControl-automatic-stepSet'!F6 -> mc:a:stepSetting:motor:5:chargingCorrectionStep:1_W
C45: ='MotionControl-automatic-stepSet'!F7 -> mc:a:stepSetting:motor:5:chargingCorrectionStep:2_W
C46: ='MotionControl-automatic-stepSet'!F8 -> mc:a:stepSetting:motor:5:chargingCorrectionStep:3_W
C47: ='MotionControl-automatic-stepSet'!F9 -> mc:a:stepSetting:motor:5:IrradiationCorrectionStep:1_W
C48: ='MotionControl-automatic-stepSet'!F10 -> mc:a:stepSetting:motor:5:IrradiationCorrectionStep:2_W
...
